<?xml version="1.0"?>
<!--
Software License Agreement (BSD License)

Copyright (c) 2020, Exobotic
All rights reserved.

Redistribution and use in source and binary forms, with or without
modification, are permitted provided that the following conditions
are met:

 * Redistributions of source code must retain the above copyright
   notice, this list of conditions and the following disclaimer.
 * Redistributions in binary form must reproduce the above
   copyright notice, this list of conditions and the following
   disclaimer in the documentation and/or other materials provided
   with the distribution.
 * Neither the name of Exobotic nor the names of its
   contributors may be used to endorse or promote products derived
   from this software without specific prior written permission.

THIS SOFTWARE IS PROVIDED BY THE COPYRIGHT HOLDERS AND CONTRIBUTORS
"AS IS" AND ANY EXPRESS OR IMPLIED WARRANTIES, INCLUDING, BUT NOT
LIMITED TO, THE IMPLIED WARRANTIES OF MERCHANTABILITY AND FITNESS
FOR A PARTICULAR PURPOSE ARE DISCLAIMED. IN NO EVENT SHALL THE
COPYRIGHT OWNER OR CONTRIBUTORS BE LIABLE FOR ANY DIRECT, INDIRECT,
INCIDENTAL, SPECIAL, EXEMPLARY, OR CONSEQUENTIAL DAMAGES (INCLUDING,
BUT NOT LIMITED TO, PROCUREMENT OF SUBSTITUTE GOODS OR SERVICES;
LOSS OF USE, DATA, OR PROFITS; OR BUSINESS INTERRUPTION) HOWEVER
CAUSED AND ON ANY THEORY OF LIABILITY, WHETHER IN CONTRACT, STRICT
LIABILITY, OR TORT (INCLUDING NEGLIGENCE OR OTHERWISE) ARISING IN
ANY WAY OUT OF THE USE OF THIS SOFTWARE, EVEN IF ADVISED OF THE
POSSIBILITY OF SUCH DAMAGE.
-->

<robot name="fieldbot" xmlns:xacro="http://www.ros.org/wiki/xacro">

	<!-- Constants for robot dimensions -->
	<xacro:property name="PI" value="3.1415926535897931"/>
	<xacro:property name="DEG2RAD" value="0.017453292519943295"/>
	<xacro:property name="l1" value="0.17" /> <!-- length from theta1 to theta2 -->
	<xacro:property name="dr" value="0.19" /> <!-- rotor diameter -->

	<!-- Import Rviz colors -->
	<xacro:include filename="$(find iwp_bringup)/urdf/materials.xacro" />

	<link name="base_link">
		<collision>
			<origin xyz="0 0 0" rpy="0 0 0"/>
			<geometry>
				<box size="0.1 0.1 0.1"/>
			</geometry>
		</collision>
		<visual>
			<origin xyz="0 0 0" rpy="0 0 0"/>
			<geometry>
				<box size="0.1 0.1 0.1"/>
			</geometry>
			<material name="orange"/>
		</visual>
	</link>

	<joint name="theta1" type="continuous">
		<origin xyz="0.05 0.0 0.0" rpy="0 0 0"/>
		<parent link="base_link" />
		<child link="theta1_link" />
		<dynamics damping="0.04"/>
		<axis xyz="1 0 0" />
	</joint>
	<joint name="theta2" type="continuous">
		<origin xyz="0.02 0.0 ${-l1}" rpy="0 0 0"/>
		<parent link="theta1_link" />
		<child link="theta2_link" />
		<dynamics damping="0.01"/>
		<axis xyz="1 0 0" />
	</joint>

	<link name="theta1_link">
		<collision>
			<origin xyz="0 0 0" rpy="0 0 0"/>
			<geometry>
				<cylinder radius="0.01" length="${l1}"/>
			</geometry>
		</collision>
		<visual>
			<origin xyz="0 0 0" rpy="0 0 0"/>
			<geometry>
				<cylinder radius="0.01" length="${l1}"/>
			</geometry>
			<material name="green"/>
		</visual>
		<inertial>
			<origin xyz="0 0 0" rpy="0 0 0"/>
			<mass value="1.0"/>
			<inertia ixx="0.01" ixy="0.0" ixz="0.0"
					 iyy="0.0" iyz="0.0"
					 izz="0.0"/>
		</inertial> 
	</link>
	<link name="theta2_link">
		<collision>
			<origin xyz="0 0 0" rpy="0 0 0"/>
			<geometry>
				<cylinder radius="0.01" length="${l1}"/>
			</geometry>
		</collision>
		<visual>
			<origin xyz="0 0 0" rpy="0 0 0"/>
			<geometry>
				<cylinder radius="0.01" length="${l1}"/>
			</geometry>
			<material name="green"/>
		</visual>
		<inertial>
			<origin xyz="0 0 0" rpy="0 0 0"/>
			<mass value="1.0"/>
			<inertia ixx="0.01" ixy="0.0" ixz="0.0"
					 iyy="0.0" iyz="0.0"
					 izz="0.0"/>
		</inertial> 
	</link>

	<transmission name="theta1_trans">
		<type>transmission_interface/SimpleTransmission</type>
		<joint name="theta1">
			<hardwareInterface>hardware_interface/EffortJointInterface</hardwareInterface>
		</joint>
		<actuator name="theta1_motor">
			<mechanicalReduction>1</mechanicalReduction>
		</actuator>
	</transmission>
	<transmission name="theta2_trans">
		<type>transmission_interface/SimpleTransmission</type>
		<joint name="theta2">
			<hardwareInterface>hardware_interface/EffortJointInterface</hardwareInterface>
		</joint>
		<actuator name="theta2_motor">
			<mechanicalReduction>1</mechanicalReduction>
		</actuator>
	</transmission>

</robot>
